Workbook

Sheet All Details for ACID Pastor
A1: S.No | B1: Reg.No | C1: Name | D1: Designation | E1: Office | F1: Educational Qualification | G1: Marital Status | H1: Spouse Name | I1: Citizen | J1: Referred By | K1: D.O.B | L1: Gender | M1: E-mail Address | N1: Contact Address | O1: Church Name | P1: District | R1: Phone No. | S1: Date of Ordination | T1: 2014 | U1: 2015 | V1: 2016 | W1: 2017 | X1: 2018 | Y1: 2019 | Z1: 2020 | AA1: 2021 | AB1: 2022 | AC1: 2023 | AD1: 2024 | AE1: 2025 | AF1: No. of Renewal O1 | AG1: No. of Renewal O2 | AH1: No. of Renewal O3 | AI1: No. of Renewal O4 | AJ1: No. of Renewal O5 | AK1: No. of Renewal O6 | AL1: No. of Renewal O7 | AM1: No. of Renewal O8 | AN1: No. of Renewal O9 | AO1: No. of Renewal O10 | AP1: No. of Renewal O11 | AQ1: No. of Renewal O12 | AR1: No. of Renewal O13 | AS1: No. of Renewal O14 | AT1: No. of Renewal O15 | AU1: No. of Renewal O16 | AV1: No. of Renewal O17 | AW1: No. of Renewal O18 | AX1: No. of Renewal O19 | AY1: 2026 | AZ1: Status | BA1: No. of Renewal O20 | BB1: No. Of Renewal 021 | BC1: No. Of Renewal 022 | BD1: No. Of Renewel 023 | BE1: No. Of Renewel 024 | BF1: Total
A2: 1 | B2: TN0001 | C2: Rt.Rev. S. Johnson Durai | D2: Bishop &chairman/synod member | E2: Bishop | K2: 10.06.1966 | L2: M | M2: revjohnsondurai@gmail.com | N2: 7-1-18B 2/1, Thiyaki Alagarsamy Street, Anna Nagar, Batlagundu, Dindigul - 624202. | O2: Power In The Word Church | P2: Dindigul | Q2: Tamil Nadu | R2: 9486485810 | AF2: - | AZ2: Active | BF2: -
A3: 2 | B3: TN0003 | C3: Rev. T. Anandaraj | D3: Member | E3: Pastor | J3: Rt. Rev. S. Johnson Durai | K3: 11.07.1970 | L3: M | M3: anand@fficc.org.in | N3: Shalom, 25 RR Gardens, Edayarpalayam, Coimbatore – 641 012, Tamil Nadu. | O3: Faith Family International Christian Center | P3: Coimbatore | Q3: Tamil Nadu | R3: +91 9244836354 | S3: 10.10.2013 O1 | AF3: =COUNTA('All Details for ACID Pastor'!$T3:$AB3) -> 0 | AZ3: Active | BF3: =COUNTA('All Details for ACID Pastor'!$T3:$AB3) -> 0
A4: 3 | B4: TN0005 | C4: Rev. R. John Durai | D4: Vice Chairman/Synod Member | E4: Evangelist | K4: 06.08.1958 | L4: M | M4: rjdwonder@yahoo.com | N4: Plot No. 4, Anbu Nagar 2nd Street, Opp. Ellis Nagar Telephone Exchange, Madurai – 625 010, Tamil Nadu. | O4: Wonder Word Ministries | P4: Madurai | Q4: Tamil Nadu | R4: +91 9842115753 | S4: 10.10.2013 O1 | T4: 16.10.2014 | AF4: =COUNTA('All Details for ACID Pastor'!$T4:$AB4) -> 1 | AZ4: Active | BF4: =COUNTA('All Details for ACID Pastor'!$T4:$AB4) -> 1
A5: 4 | B5: TN0007 | C5: Rev. A. Pounraj | D5: Trustee | E5: Pastor | J5: Rt. Rev. S. Johnson Durai | K5: 10.11.1973 | L5: M | N5: No:135, Kaloor Road, Appasamy Nagar, Tindivanam – 604 002, Tamil Nadu. | O5: Apostolic Fellowship Tabernacle | P5: Villupuram | Q5: Tamil Nadu | R5: +91 9894961442 | S5: 10.10.2013 O1 | T5: 16.10.2014 | AF5: =COUNTA('All Details for ACID Pastor'!$T5:$AB5) -> 1 | AZ5: Active | BF5: =COUNTA('All Details for ACID Pastor'!$T5:$AB5) -> 1
A6: 5 | B6: TN0008 | C6: Rev. K. Daniel Hagin | D6: Member | E6: Pastor | J6: Rt. Rev. S. Johnson Durai | K6: 15.05.1976 | L6: M | M6: danielhagin@gmail.com | N6: 2/32, Fathima TheaterRoad, Anna Nagar, Allinagaram – 625 531, Theni (Dt),Tamil Nadu. | O6: God’s Word Church | P6: Theni | Q6: Tamil Nadu | R6: +91 99941 80893 | S6: 10.10.2013 O1 | T6: 12.02.2015 | U6: 12.10.2015 | V6: 12.10.2016 | W6: 12.10.2017 | X6: 16.10.2018 | Y6: 15.10.2019 | AA6: 13/10/2021 | AC6: 11.10.2023 | AF6: =COUNTA('All Details for ACID Pastor'!$T6:$AB6) -> 7 | AZ6: Active | BF6: 8
A7: 6 | B7: TN0009 | C7: Rev. A. Vanjinathan | D7: Member | E7: Pastor | J7: Rev.M. R. Davidraj | K7: 07.06.1974 | L7: M | M7: ifmtrust@gmail.com | N7: No.5 Chakkaravarthi School, Mamarathupatti Road,Usilampatti - 625532, Theni [Dt], Tamil Nadu. | O7: Apostolic Fellowship Tabernacle Church | P7: Madurai | Q7: Tamil Nadu | R7: +91 9940835781 | S7: 10.10.2013 O1 | T7: 12.02.2015 | U7: 12.10.2015 | V7: 12.10.2016 | W7: 12.10.2017 | X7: 24.01.2018 | Y7: 11.04.2019 | Z7: 13/10/2021 | AA7: 13/10/2021 | AB7: 13/10/2021 | AF7: =COUNTA('All Details for ACID Pastor'!$T7:$AB7) -> 9 | AZ7: Active | BF7: =COUNTA('All Details for ACID Pastor'!$T7:$AB7) -> 9
A8: 7 | B8: TN0010 | C8: Rev. M. Samuel | D8: Synod Member | E8: Pastor | J8: Rev. R. Gnanainbavanan | K8: 09.05.1974 | L8: M | M8: samsatheeshmaha224@gmail.com | N8: Plot No.28, Alagu Nagar, Eb Colony, Sornamahal Plot, Batlagundu – 624 202,Dindigul (Dt), Tamil Nadu. | O8: Meetpar Church | P8: Dindigul | Q8: Tamil Nadu | R8: 91 98659 46224 | S8: 10.10.2013 O1 | T8: 16.10.2014 | U8: 16.10.2015 | V8: 08.11.2016 | W8: 12.10.2017 | X8: 16.10.2018 | Y8: 02.11.2019 | AF8: =COUNTA('All Details for ACID Pastor'!$T8:$AB8) -> 6 | AZ8: Active | BF8: =COUNTA('All Details for ACID Pastor'!$T8:$AB8) -> 6
A9: 8 | B9: TN0011 | C9: Rev. I. Thilipkumar | D9: Member | E9: Pastor | J9: Rt. Rev. S. Johnson Durai | K9: 03.02.1961 | L9: M | M9: revthilipncm@gmail.com | N9: 2 - 420 (1/2/3) I, Kurinji Nagar, Gandhi Nagar, Batlagundu (Po), Dindigul, Tamil Nadu - 624202. | O9: New Covenant Ministries Church | P9: Dindigul | Q9: Tamil Nadu | R9: 91 98652 78962 | S9: 10.10.2013 O1 | U9: 12.04.2023 | V9: 12.04.2023 | W9: 12.04.2023 | X9: 12.04.2023 | Y9: 12.04.2023 | Z9: 12.04.2023 | AA9: 12.04.2023 | AB9: 12.04.2023 | AC9: 12.04.2023 | AZ9: Active | BB9: 9 | BF9: 9
A10: 9 | B10: TN0012 | C10: Rev. R. Gnana Inbavanan | D10: D. O. S & Synod Member | E10: Pastor | J10: John Peter | K10: 07.05.1959 | L10: M | N10: Blessed Hope Fellowship Church, Gandhi Nagar Main Road, Batlagundu – 624202. Dindigul District. Tamil Nadu. | O10: Blessed Hope Fellowship Church | P10: Dindigul | Q10: Tamil Nadu | R10: +91 9787023637 | S10: 10.10.2013 O1 | T10: 12.02.2015 | U10: 16.10.2015 | V10: 12.10.2016 | W10: 12.10.2017 | X10: 16.10.2018 | Y10: 13/10/2021 | Z10: 13/10/2021 | AA10: 13/10/2021 | AF10: =COUNTA('All Details for ACID Pastor'!$T10:$AB10) -> 8 | AZ10: Active | BF10: =COUNTA('All Details for ACID Pastor'!$T10:$AB10) -> 8
A11: 10 | B11: TN0014 | C11: Rev. R. Elisha Anbu | D11: Member | E11: Apostle Pastor | J11: Rev.M. R. Davidraj | K11: 01.01.1977 | L11: F | M11: pastorelishaanbu@gmail.com | N11: Foundation On The Holy Word Church, Kakkanji Nagar, E.Pudukodai, Periyakulam (Tk), Theni – 625 605, Tamil Nadu. | O11: Foundation On The Holy Word Church | P11: Theni | Q11: Tamil Nadu | R11: +91 90472 76721 | S11: 10.10.2013 O1 | T11: 04.11.2014 | U11: 25.02.2020 | V11: 25.02.2020 | W11: 25.02.2020 | X11: 25.02.2020 | Y11: 25.02.2020 | AF11: =COUNTA('All Details for ACID Pastor'!$T11:$AB11) -> 6 | AZ11: Active No response | BF11: =COUNTA('All Details for ACID Pastor'!$T11:$AB11) -> 6
A12: 11 | B12: TN0015 | C12: Rev. M. Paul David | D12: Member | J12: Rt. Rev. S. Johnson Durai | K12: 25.05.1978 | L12: M | M12: pauldd@gmail.com | N12: 50-1, Avin Nagar, Vandiyur – 625 020,Madurai (Dt), Tamil Nadu. | O12: Living Light Church | P12: Madurai | Q12: Tamil Nadu | R12: +91 99522 00361 | S12: 10.10.2013 O1 | AF12: =COUNTA('All Details for ACID Pastor'!$T12:$AB12) -> 0 | AZ12: In active | BF12: =COUNTA('All Details for ACID Pastor'!$T12:$AB12) -> 0
A13: 12 | B13: TN0016 | C13: Rev. A. Epsebai | D13: Member | E13: Associate Pastor | J13: Rt. Rev. S. Johnson Durai | K13: 24.03.1964 | L13: F | N13: 7/1/18B2/1, Thiyaki Anlagarsamy St, Annanagar,Batlagundu-624202, Dindigul[Dt] Tamilnadu. | O13: Power In The Word Church | P13: Dindigul | Q13: Tamil Nadu | R13: 91 9486907064 | S13: 10.10.2013 O1 | T13: 16.10.2014 | U13: 24.10.2015 | V13: 12.04.2022 | W13: 12.04.2022 | X13: 12.04.2022 | Y13: 12.04.2022 | Z13: 12.04.2022 | AA13: 12.04.2022 | AB13: 12.04.2022 | AF13: =COUNTA('All Details for ACID Pastor'!$T13:$AB13) -> 9 | AZ13: Active | BF13: =COUNTA('All Details for ACID Pastor'!$T13:$AB13) -> 9
A14: 13 | B14: TN0018 | C14: Mrs. A. Helen Ruth | D14: Member | E14: Associate Pastor | J14: Rev. T. Anandaraj | K14: 31.03.1970 | L14: F | M14: helen@fficc.org.in | N14: Faith Family International Christian Center, Shalom, 25, RR Gardens, Edayarpalayam, Coimbatore – 641 012. Tamil Nadu. | O14: Faith Family International Christian Center | P14: Coimbatore | Q14: Tamil Nadu | R14: 91 9150185391 | S14: 10.10.2013 O1 | T14: 30.05.2015 | U14: 15.01.2016 | AF14: =COUNTA('All Details for ACID Pastor'!$T14:$AB14) -> 2 | AZ14: Active | BF14: =COUNTA('All Details for ACID Pastor'!$T14:$AB14) -> 2
A15: 14 | B15: TN0022 | C15: Rev. Daniel A. Swaminathan | D15: Member | E15: Pastor | J15: Rev.M. R. Davidraj | K15: 01.01.1959 | L15: M | N15: Jesus The Way Grace Ministries, PTR Nagar, Kalmedu, Sakkimangalam – 625 201 Madurai (Dt), Tamil Nadu. | O15: Jesus The Way Grace Ministries | P15: Madurai | Q15: Tamil Nadu | R15: +91 96552 10719 | S15: 10.10.2013 O1 | T15: 16.10.2014 | U15: 12.04.2018 | V15: 12.04.2018 | W15: 12.04.2018 | X15: 25.02.2020 | Y15: 25.02.2020 | AF15: =COUNTA('All Details for ACID Pastor'!$T15:$AB15) -> 6 | AZ15: Active | BF15: =COUNTA('All Details for ACID Pastor'!$T15:$AB15) -> 6
A16: 15 | B16: TN0023 | C16: Rev. B. Sesan George | D16: D.O.S | E16: Pastor | J16: Rt. Rev. S. Johnson Durai | K16: 06.09.1971 | L16: M | N16: Church Of God, Mohan Nagar 1st Street,Sugar Factory (Opp), Pugalur. – 639 113.Karur [Dt], Tamil Nadu. | O16: Church Of God | P16: Karur | Q16: Tamil Nadu | R16: 89258 01073 | S16: 10.10.2013 O1 | T16: 16.10.2014 | U16: 16.10.2015 | V16: 12.10.2016 | W16: 12.04.2018 | X16: 11.04.2019 | Y16: 16.10.2019 | AF16: =COUNTA('All Details for ACID Pastor'!$T16:$AB16) -> 6 | AZ16: Active | BF16: =COUNTA('All Details for ACID Pastor'!$T16:$AB16) -> 6
A17: 16 | B17: TN0024 | C17: Rev. S. Stephen Nagappan | D17: Member | E17: Pastor | K17: 18.08.1970 | L17: M | N17: 2/1102a, State Bank Colony, Satchiyapuram, Sivakasi – 626 124,Virudhunagar [Dt], Tamil Nadu. | O17: Word Of God Prayer House | P17: Viruthunagar | Q17: Tamil Nadu | R17: +91 9944413575 | S17: 10.10.2013 O1 | T17: 16.10.2014 | U17: 14.10.2017 | V17: 14.10.2017 | W17: 11.04.2019 | X17: 11.04.2019 | AF17: =COUNTA('All Details for ACID Pastor'!$T17:$AB17) -> 5 | AZ17: Active | BF17: =COUNTA('All Details for ACID Pastor'!$T17:$AB17) -> 5
A18: 17 | B18: TN0025 | C18: Rev. R. David Pachaimuthu | D18: Member | E18: Pastor | J18: Pr. P. Immanuel | K18: 05.06.1969 | L18: M | N18: Malaival Maruvzhvu Christian Church, Palkadai Village, Vadakadu – 624 619, Oddanchatram Taluk, Dindigul [Dt], Tamil Nadu. | O18: Malaival Maruvzhvu Christian Church | P18: Dindigul | Q18: Tamil Nadu | R18: +91 9488243775 | S18: 10.10.2013 O1 | T18: 22.12.2014 | U18: 12.02.2015 | V18: 12.10.2016 | W18: 12.10.2017 | X18: 12.04.2018 | Y18: 16.10.2018 | Z18: 15.10.2019 | AF18: =COUNTA('All Details for ACID Pastor'!$T18:$AB18) -> 7 | AZ18: Active | BF18: =COUNTA('All Details for ACID Pastor'!$T18:$AB18) -> 7
A19: 18 | B19: TN0026 | C19: Rev. S. Sundaram | D19: Member | E19: Pastor | J19: Rev.M. R. Davidraj | K19: 16.06.1964 | L19: M | N19: 27 – N – 102, Adhi Dravidar Street, Vettamangalam, Melbagam – 639 117, Karur (Dt), Tamil Nadu. | O19: Voice Of El-Shadai Ministry | P19: Karur | Q19: Tamil Nadu | R19: +91 80988 22759 | S19: 10.10.2013 O1 | T19: 16.10.2014 | U19: 19.04.2017 | V19: 19.04.2017 | AF19: =COUNTA('All Details for ACID Pastor'!$T19:$AB19) -> 3 | AZ19: In active | BF19: =COUNTA('All Details for ACID Pastor'!$T19:$AB19) -> 3
A20: 20 | B20: TN0028 | C20: Rev. V. David @ Senthil Kumaran | D20: Member | E20: Pastor | J20: Rev. A. Chinnappadoss | K20: 12.12.1969 | L20: M | M20: theshoutofaking@gmail.com | N20: Thideer Colony, Meenampatti North, Sivakasi –626 189, Virudhunagar [Dt], Tamil Nadu. | O20: Open Bible Church Of God | P20: Viruthunagar | Q20: Tamil Nadu | R20: 97518 56777 | S20: 10.10.2013 O1 | T20: 16.10.2014 | U20: 19.04.2017 | AF20: =COUNTA('All Details for ACID Pastor'!$T20:$AB20) -> 2 | AZ20: In active | BF20: =COUNTA('All Details for ACID Pastor'!$T20:$AB20) -> 2
A21: 21 | B21: TN0029 | C21: Rev. A.J. Amos Moorthy | D21: Member | E21: Pastor | J21: Rev. T. Anandaraj | K21: 10.06.1975 | L21: M | M21: mercy_chome@yahoo.com | N21: No:127/1, Main Road, Church Street, Gandhi Nagar,Vembakkam, Cheiyyar [Tk], Thiruvannamalai [Dt ] - 604 410, | O21: All India Village Christian Center | P21: Thiruvannamalai | Q21: Tamil Nadu | R21: 7845862698 | S21: 10.10.2013 O1 | AF21: =COUNTA('All Details for ACID Pastor'!$T21:$AB21) -> 0 | AZ21: In active | BF21: =COUNTA('All Details for ACID Pastor'!$T21:$AB21) -> 0
A22: 22 | B22: TN0030 | C22: Rev. S. Michael @ Baskaran | D22: Member | E22: Pastor | J22: Rev.M. R. Davidraj | K22: 28.02.1967 | L22: M | M22: tamilmissionchurch@gmail.com | N22: H – 117, Malligai Nagar, Anaiyur, Madurai - 625 017, Tamil Nadu. | O22: Tamil Mission Church | P22: Madurai | Q22: Tamil Nadu | R22: 98949 14260 | S22: 10.10.2013 O1 | T22: 12.02.2014 | U22: 12.02.2015 | V22: 11.10.2023 | W22: 11.10.2023 | X22: 11.10.2023 | Y22: 11.10.2023 | Z22: 11.10.2023 | AA22: 11.10.2023 | AB22: 11.10.2023 | AC22: 11.10.2023 | AD22: 11.10.2023 | AF22: =COUNTA('All Details for ACID Pastor'!$T22:$AB22) -> 9 | AZ22: Active | BF22: 12
A23: 23 | B23: TN0031 | C23: Rev. R. Venu Gopal | D23: Member | E23: Pastor | J23: Rev.M. R. Davidraj | K23: 05.04.1965 | L23: M | M23: kartharvenu@gmail.com | N23: 354 – N, Prof. Appadurai Compound, Kambar Cross Street, Vinayaga Nagar, Pasumalai,Madurai (Dt) – 625 004. Tamil Nadu. | O23: Grace Prayer Church | P23: Madurai | Q23: Tamil Nadu | R23: 98423 08423 | S23: 10.10.2013 O1 | AF23: =COUNTA('All Details for ACID Pastor'!$T23:$AB23) -> 0 | AZ23: In active | BF23: =COUNTA('All Details for ACID Pastor'!$T23:$AB23) -> 0
A24: 24 | B24: TN0032 | C24: Rev. M. Mohanraj | D24: Member | E24: Pastor | J24: Rev.M. R. Davidraj | K24: 12.07.1976 | L24: M | N24: 12/1/44, Middle Street, Elumalai, Peraiyur, (Tk). Madurai. (Dt) Pin-625 535. | O24: United Mission To India | P24: Madurai | Q24: Tamil Nadu | R24: 96003 56581 | S24: 10.10.2013 O1 | AF24: =COUNTA('All Details for ACID Pastor'!$T24:$AB24) -> 0 | AZ24: In active | BF24: =COUNTA('All Details for ACID Pastor'!$T24:$AB24) -> 0
A25: 25 | B25: TN0033 | C25: Rev. S. John Kennady | D25: Member | E25: Pastor | J25: Rev.M. R. Davidraj | K25: 07.02.1969 | L25: M | N25: 4/50, Kmt House, Pillaiyarnatham, Vayaloor, Madurai (Dt) – 625 402,Tamilnadu. | O25: United Mission To India | P25: Madurai | Q25: Tamil Nadu | R25: 98651 97725 | S25: 10.10.2013 O1 | AF25: =COUNTA('All Details for ACID Pastor'!$T25:$AB25) -> 0 | AZ25: In active | BF25: =COUNTA('All Details for ACID Pastor'!$T25:$AB25) -> 0
A26: 26 | B26: TN0034 | C26: Rev. A.Sudan Abraham | D26: Member | E26: Pastor | J26: Rev.M. R. Davidraj | K26: 28.12.1950 | L26: M | N26: Jesus Good News Prayer House,Keelady (Po), Silaiman, Sivagangai. Madurai (Dt), Tamil Nadu. | O26: Jesus Good News Prayer House | P26: Madurai | Q26: Tamil Nadu | R26: 96778 22261 | S26: 10.10.2013 O1 | T26: 16.10.2015 | U26: 14.02.2017 | V26: 25.02.2020 | W26: 25.02.2020 | X26: 25.02.2020 | AF26: =COUNTA('All Details for ACID Pastor'!$T26:$AB26) -> 5 | AZ26: Active | BF26: =COUNTA('All Details for ACID Pastor'!$T26:$AB26) -> 5
A27: 27 | B27: TN0035 | C27: Rev. P.K. Joshua | D27: Member | E27: Pastor | J27: Rev.M. R. Davidraj | K27: 15.06.1953 | L27: M | M27: pkjoshuaa@yahoo.co.in | N27: 10, Anand Nagar, Anayur, (Post), Madurai – 625 017, Tamil Nadu. | O27: Rehoboth Prayer House | P27: Madurai | Q27: Tamil Nadu | R27: 94424 07753 | S27: 10.10.2013 O1 | T27: 08.09.2015 | U27: 16.10.2015 | V27: 12.10.2016 | W27: 12.10.2017 | X27: 16.10.2018 | Y27: 15.10.2019 | AA27: 12.04.2022 | AB27: 12.04.2022 | AF27: =COUNTA('All Details for ACID Pastor'!$T27:$AB27) -> 8 | AZ27: Active | BF27: =COUNTA('All Details for ACID Pastor'!$T27:$AB27) -> 8
A28: 28 | B28: TN0036 | C28: Rev. P. Paul Hagin, | D28: Member | E28: Pastor | J28: Rev.M. R. Davidraj | K28: 27.05.1978 | M28: paul.hagin@gmail.com | N28: 2/58, Middle street, puduthamaraipatty post Y. Othakadai via, Madurai District 625107 | O28: Covenant Stone Ministries | P28: Madurai | Q28: Tamil Nadu | R28: 9626135877 | S28: 10.10.2013 O1 | AF28: =COUNTA('All Details for ACID Pastor'!$T28:$AB28) -> 0 | AZ28: In active | BF28: =COUNTA('All Details for ACID Pastor'!$T28:$AB28) -> 0
A29: 29 | B29: TN0037 | C29: Rev. A. Mohanraj | D29: Member | E29: Pastor | J29: Rev. R. Elisha Anbu | K29: 02.01.1982 | N29: 12-3-19, Srimoogambigai Nagar, Karattupatti Melechokkanathapuram [Po] – 625582, Bodinayakkanur, Theni [Dt], Tamil Nadu. | O29: Jesus Miracle Ministry | P29: Theni | Q29: Tamil Nadu | R29: 94429 95950 | S29: 10.10.2013 O1 | T29: 16.10.2014 | AF29: =COUNTA('All Details for ACID Pastor'!$T29:$AB29) -> 1 | AZ29: Visited | BF29: =COUNTA('All Details for ACID Pastor'!$T29:$AB29) -> 1
A30: 31 | B30: TN0039 | C30: Rev. J. Vincent | D30: Member | E30: Pastor | J30: Rev. R. Elisha Anbu | K30: 05.03.1969 | N30: Puthukadu, Obsarvatory (Po) - 624 103, Kodaikannal [Tk], Dindigul (Dt), Tamil Nadu. | O30: Ipc Church | P30: Dindigul | Q30: Tamil Nadu | R30: 80980 94017 | S30: 10.10.2013 O1 | T30: 12.04.2016 | AF30: =COUNTA('All Details for ACID Pastor'!$T30:$AB30) -> 1 | AZ30: In active | BF30: =COUNTA('All Details for ACID Pastor'!$T30:$AB30) -> 1
A31: 32 | B31: TN0040 | C31: Rev. R. Gnanamuthu @ Marimuthu | D31: Member | E31: Pastor | J31: Rev. R. Elisha Anbu | K31: 30.05.1967 | N31: 95 A, North Street, South Venganalloor [Po] – 626 142, Chithambarapuram, Rajapalayam [Tk], Virudhunagar [Dt] Tamil Nadu. | O31: Zion Church | P31: Viruthunagar | Q31: Tamil Nadu | R31: 9597359703 | S31: 10.10.2013 O1 | AF31: =COUNTA('All Details for ACID Pastor'!$T31:$AB31) -> 0 | AZ31: In active | BF31: =COUNTA('All Details for ACID Pastor'!$T31:$AB31) -> 0
A32: 33 | B32: TN0042 | C32: Rev. D. Stephen | D32: Member | J32: Pr. S. Sundram | K32: 28.05.1960 | N32: 93 – Kamaraj Street, Railway Station Back Side, Covery Nagar, Kulithalai – 639 104, Karur (Dt).Tamil Nadu. | O32: Faith Prayer House | P32: Karur | Q32: Tamil Nadu | R32: 74183 23523 | S32: 10.10.2013 O1 | T32: 11.11.2014 | U32: 31.01.2017 | V32: 31.01.2017 | W32: 25.02.2020 | X32: 25.02.2020 | Y32: 25.02.2020 | AF32: =COUNTA('All Details for ACID Pastor'!$T32:$AB32) -> 6 | AZ32: Active | BF32: =COUNTA('All Details for ACID Pastor'!$T32:$AB32) -> 6
A33: 34 | B33: TN0043 | C33: Rev. D. Duraisingh | D33: Member | E33: Pastor | J33: Rev. S. Sambath Solomon | K33: 03.01.1975 | N33: Church Of New Grace, Main Road, Kullappagoundanpatty, Cumbum (Via), Theni [Dt] – 625 516, Tamil Nadu. | O33: Church Of New Grace | P33: Theni | Q33: Tamil Nadu | R33: 9159703810 | S33: 10.10.2013 O1 | T33: 12.02.2015 | U33: 25.02.2020 | V33: 25.02.2020 | W33: 25.02.2020 | X33: 25.02.2020 | Y33: 25.02.2020 | Z33: 25.02.2020 | AF33: =COUNTA('All Details for ACID Pastor'!$T33:$AB33) -> 7 | AZ33: Active No response | BF33: =COUNTA('All Details for ACID Pastor'!$T33:$AB33) -> 7
A34: 35 | B34: TN0044 | C34: Rev.P. Thaga Raju | D34: Member | J34: Pr. S. Sundram | K34: 15.05.1958 | N34: Jesus Love’s Ministry, Sarakkampatty, Veeranampatty, Kadavoor (Tk), Karur [Dt]– 621 301, Tamil Nadu. | O34: Jesus Love’s Ministry | P34: Karur | Q34: Tamil Nadu | R34: 91592 47093 | S34: 10.10.2013 O1 | T34: 16.10.2015 | AF34: =COUNTA('All Details for ACID Pastor'!$T34:$AB34) -> 1 | AZ34: In active | BF34: =COUNTA('All Details for ACID Pastor'!$T34:$AB34) -> 1
A35: 36 | B35: TN0045 | C35: Rev. S. Joseph Vimal Raj | D35: Member | E35: Worship Leader | J35: Pr. S. Sundram | K35: 04.12.1992 | M35: vimalraj1992@gmail.com | N35: 102, Vettamangalam, Vettamangalam– 639 117, Karur [Dt], Tamil Nadu. | O35: Elshaddai Believer’s Church | P35: Karur | Q35: Tamil Nadu | R35: 86755 52384 | S35: 10.10.2013 O1 | T35: 16.10.2014 | AF35: =COUNTA('All Details for ACID Pastor'!$T35:$AB35) -> 1 | AZ35: In active | BF35: =COUNTA('All Details for ACID Pastor'!$T35:$AB35) -> 1
A36: 37 | B36: TN0046 | C36: Rev. R. Ealiya | D36: Member | E36: Pastor | J36: Rev. J. Job | K36: 07.03.1982 | N36: 8. W/223, Seetharam Nagar, Sakkampatty, Antipatty, Theni (Dt) - 625 512. Tamil Nadu. | O36: Aci – Ulagaratchagar Jesus Ministry | P36: Theni | Q36: Tamil Nadu | R36: 99658 39209 | S36: 10.10.2013 O1 | T36: 04.11.2014 | U36: 16.10.2015 | V36: 16.10.2018 | W36: 16.10.2018 | X36: 16.10.2018 | AF36: =COUNTA('All Details for ACID Pastor'!$T36:$AB36) -> 5 | AZ36: Active Visited | BF36: =COUNTA('All Details for ACID Pastor'!$T36:$AB36) -> 5
A37: 38 | B37: TN0047 | C37: Rev. D. Yesupatham | D37: Member | E37: Pastor | J37: Rev. J. Job | K37: 19.06.1975 | N37: Cef – Glory Of Church, Anna Nagar, Madurai Road, Theni – 625 531. Tamil Nadu. | O37: Cef – Glory Of Church | P37: Theni | Q37: Tamil Nadu | R37: 77084 11074 | S37: 10.10.2013 O1 | T37: 04.11.2014 | AF37: =COUNTA('All Details for ACID Pastor'!$T37:$AB37) -> 1 | AZ37: In active No response | BF37: =COUNTA('All Details for ACID Pastor'!$T37:$AB37) -> 1
A38: 39 | B38: TN0048 | C38: Rev. A. Chinnappadoss | D38: D.O.S | E38: Pastor | J38: Rev. J. Job | K38: 30.11.1974 | L38: M | M38: jeevapathailsvk@gmail.com | N38: 3/274 – D5 Mayiladundurai, Anuppankulam – 626 189, Sivakasi [Tk], Virudhunagar [Dt], Tamil Nadu. | O38: Apostolic Christian Ministries Foundation | P38: Viruthunagar | Q38: Tamil Nadu | R38: 99446 62106 | S38: 10.10.2013 O1 | T38: 04.11.2014 | U38: 16.10.2015 | V38: 19.04.2016 | W38: 12.04.2018 | X38: 16.10.2018 | Y38: 03.12.2019 | Z38: 13/10/2021 | AA38: 13/10/2021 | AB38: 13/10/2021 | AD38: 10.04.2024 | AF38: =COUNTA('All Details for ACID Pastor'!$T38:$AB38) -> 9 | AZ38: Active | BE38: 1 | BF38: 10
A39: 40 | B39: TN0049 | C39: Rev. K. Joshua | D39: Member | E39: Pastor | J39: Rev. J. Job | K39: 30.07.1980 | N39: Living Jesus Ministries, Vaigaipudur,Vaigaidam, Theni [Dt] – 625 562, Tamil Nadu. | O39: Living Jesus Ministries | P39: Theni | Q39: Tamil Nadu | R39: 9843882971 | S39: 10.10.2013 O1 | T39: 16.10.2014 | U39: 16.10.2015 | AF39: =COUNTA('All Details for ACID Pastor'!$T39:$AB39) -> 2 | AZ39: Not Willing | BF39: =COUNTA('All Details for ACID Pastor'!$T39:$AB39) -> 2
A40: 41 | B40: TN0050 | C40: Rev. I. Christhudas | D40: Member | E40: Pastor | J40: Rev. J. Job | K40: 13.01.1965 | N40: W4b8 – 14, Main Street, Rathinam Nagar, Theni (Dt) – 625 531, Tamil Nadu. | O40: Hossannah Prayer House | P40: Theni | Q40: Tamil Nadu | R40: 97900 81404 | S40: 10.10.2013 O1 | T40: 16.10.2014 | AF40: =COUNTA('All Details for ACID Pastor'!$T40:$AB40) -> 1 | AZ40: In active To be visit | BF40: =COUNTA('All Details for ACID Pastor'!$T40:$AB40) -> 1
...

Sheet D.O.S
A1: S.No | B1: Reg.No | C1: Name | D1: Designation | E1: District | F1: Reference Details | G1: Address | H1: Phone No.
A2: 1 | B2: TN0023 | C2: Rev. B. Sesan George | D2: D.O.S | E2: Karur | F2: Rt. Rev. S. Johnson Durai | G2: Church Of God, Mohan Nagar 1st Street,Sugar Factory (Opp), Pugalur. – 639 113.Karur [Dt], Tamil Nadu. | H2: 89258 01073
A3: 2 | B3: TN0048 | C3: Rev. A. Chinnappadoss | D3: D.O.S | E3: Virudhunagar | F3: Rev. J. Job | G3: Apostolic Christian Ministries Foundation 3/274 – D5 Mayiladundurai, Anuppankulam – 626 189, Sivakasi [Tk], Virudhunagar [Dt], Tamil Nadu. | H3: 99446 62106
A4: 3 | B4: TN0082 | C4: Rev. J. Amburose | D4: D.O.S | E4: Idukki South | F4: Rev. S. Sambath Solomon | G4: Dymock Estate Post, Vandiperiyar – 685553, Idukki District, Kerala State. | H4: 9645478988
A5: 4 | B5: TN0099 | C5: Rev. T. Sebastian | D5: D.O.S | E5: Pudhuchery | F5: Rev. John Sesaron | G5: 12, Kurunji Street, Kamaraj Nagar, Gorimedu, Pondicherry – 605006 | H5: 9345421267
A6: 5 | B6: TN0102 | C6: Rev. M.Chinnathambi Yesudos | D6: D.O.S | E6: Idukki North | F6: Rev. A. Mohan Raj | G6: Faith Prayer Fellowship Church, 251, Sureyanalli [Po], Idukki [Dt], Munnar, Kerala - 685618, | H6: 9495838152
A7: 6 | B7: TN0187 | C7: Rev. F. Anthony Raj | D7: Zonal Head | E7: Trichy | G7: Vinnaha Thoothu No.3/842, Venugopal Nagar 2ndstreet, North Kattur, Trichy – 620019, Tamilnadu. | H7: 9543519573
A8: 7 | B8: TN0214 | C8: Rev. G. Edwin Joseph Selvaraj | D8: D.O.S | E8: Trichy | F8: Rev. F. Anthony Raj | G8: Bethel Faith Prayer House 27, 2nd Street, Mannarpuram, Trichy – 620020, Tamilnadu. | H8: 9842863701
A9: 8 | B9: TN0368 | C9: Rev. C. John Subar Singh | D9: D.O.S | E9: Kanniyakumar | F9: Rev. S. Baisil | G9: 9/10 B, Palla Vilai Melmidalam-629152 Vilavancode, Kanniyakumari[Dt] Tamilnadu. | H9: 7639447591
A10: 9 | B10: TN0413 | C10: Rev. S. Anand | D10: D.O.S | E10: Kanchipuram East | F10: Rev. S. Stephen Nagappan | G10: Creator Mission Church 389, TTC Nagar, Adhanoor, Guduvancheri,Sriperumpathur [Tk], Kanchipuram [Dt] – 603202, Tamilnadu. | H10: 9176539539
A11: 10 | B11: TN0518 | C11: Rev.B.Simson | D11: D.O.S | E11: Vellore | F11: Rev. Y. Santhakumar | G11: 124/53,Meddu Street Balur Vill Kothur (PO)-635808 Gudiyatham,Vellore[Dt] Tamilnadu. | H11: 9943759925
A12: 11 | B12: TN0007 | C12: Rev. A. Pounraj | D12: Zonal Head | E12: Villupuram | F12: Rt. Rev. S. Johnson Durai | G12: Apostolic Fellowship Tabernacle, No:135, Kaloor Road, Appasamy Nagar, Tindivanam – 604 002, Tamil Nadu. | H12: 9894961442
A13: 12 | B13: TN0466 | C13: Rev. D. Antoni Raj | D13: Trustee | E13: Trichy | F13: Rev. F. Anthony Raj | G13: Living Redeemer Church A-304 - Vel Avenue, 11/1 – Royal Road, Cantonment – 620001, Trichy [Dt], Tamilnadu. | H13: 9842416106
A14: 13 | B14: TN0249 | C14: Rev. P. Santhosam | D14: D.O.S | E14: Kanchipuram | F14: Rev. S. Adham | G14: New Covenant Gospel Church No.202, Mariamman Koil, Agaram - Village, Thennari (Po) - 631604, Kanchipuram, Tamilnadu. | H14: 9789253631
A15: 14 | B15: TN0283 | C15: Rev. Y. Santhakumar | D15: D.O.S | E15: Krishnagiri | F15: Rev. C. K. Daniel Kesavan | G15: Christ Church 24/1, Kathavani, Karappattu (Po) – 635207, Uthangarai (Tk), Krishnagiri (Dt), Tamilnadu. | H15: 9443390461
A16: 15 | B16: TN0012 | C16: Rev. R. Gnana Inbavanan | D16: D.O.S | E16: Dindigul | F16: John Peter | G16: Blessed Hope Fellowship Church, Gandhi Nagar Main Road, Batlagundu – 624202. Dindigul District. Tamil Nadu. | H16: +91 9787023637
A17: 16 | B17: TN0135 | C17: Rev. D. John Abraham | D17: D.O.S | E17: Tirunelveli | F17: Rev. D. K. Deva Athisayam | G17: Karunya Penticostal Church 17/1 Indra Nagar, Pathai [Po]- 627501, Kalakkadu [Via],Nanguneri [Tk], Nellai [Dt], Tamil Nadu. | H17: 9791758596

Sheet Marriage Registration
A1: Reg.No | B1: Date | C1: Book Number | D1: Name | E1: Ministering Location | F1: Before Banns | G1: After Banns | H1: Marriage Register | I1: Status | J1: 2014 -2015 | K1: 2015 - 2016 | L1: 2016-2017 | M1: 2017-2018 | N1: 2018-2019 | O1: 2019-2020
F2: From - To | G2: From - To | H2: From - To
A3: TN0001 | B3: 16.10.2013 | C3: 1 | D3: Rt. Rev. S. Johnson Durai | E3: Dindigul | F3: 01 _ 20 | G3: 01 _ 20 | H3: 01 _ 20 | I3: Not | J3: 4 | K3: 1 | L3: 1 | M3: 1
A4: TN0002 | B4: 16.10.2013 | C4: 2 | D4: Rev. Dr. Gabriel James | E4: Nagarcoil | F4: 21_40 | G4: 21_40 | H4: 21_40 | I4: Returned
A5: TN0003 | B5: 16.10.2013 | C5: 3 | D5: Rev. T. Anandraj | E5: Coimbatore | F5: 41_60 | G5: 41_60 | H5: 41_60 | I5: Returned
A6: TN0004 | B6: 16.10.2013 | C6: 4 | D6: Rev. Clemant Alex | E6: Chennai | F6: 61_80 | G6: 61_80 | H6: 61_80 | I6: Not
A7: TN0006 | B7: 16.10.2013 | C7: 5 | D7: Rev. M. R. Davidraj | E7: Madurai | F7: 81_100 | G7: 81_100 | H7: 81_100 | I7: Not
A8: TN0007 | B8: 16.10.2013 | C8: 6 | D8: Rev. A. Pounraj | E8: Chennai | F8: 101_ 120 | G8: 101_ 120 | H8: 101_ 120 | I8: Not | N8: 2
A9: TN0024 | D9: Rev. S. Stephen Nagappan | E9: Sivakasi | F9: 121 _140 | G9: 121 _140 | H9: 121 _140
A10: TN0089 | B10: 12.02.2014 | C10: 7 | D10: Rev. P. Pavlraj Kirubakaran | E10: Sivakasi | F10: 121 _140 | G10: 121 _140 | H10: 121 _140 | I10: Not | J10: 15 | L10: 5 | O10: 1
A11: TN0029 | B11: 12.02.2014 | C11: 8 | D11: Rev. Amos | E11: Thiruvannamalai | F11: 141_160 | G11: 141_160 | H11: 141_160 | I11: Returned
A12: TN0013 | B12: 12.04.2014 | C12: 9 | D12: Rev. j. Job | E12: Theni | F12: 161_ 180 | G12: 161_ 180 | H12: 161_ 180 | I12: Not
A13: TN0023 | B13: 12.04.2014 | C13: 10 | D13: Rev. Sean George | E13: Karur | F13: 181_ 200 | G13: 181_ 200 | H13: 181_ 200 | I13: Not
A14: TN0021 | B14: 12.04.2014 | C14: 11 | D14: Rev. Sampath Salomon | E14: Uthama Palayam | F14: 201_ 220 | G14: 201_ 220 | H14: 201_ 220 | I14: Not
A15: TN0082 | B15: 12.04.2014 | C15: 12 | D15: Rev. J. Ambrose | E15: Vandiperiyar | F15: 221_ 240 | G15: 221_ 240 | H15: 221_ 240 | I15: Not
A16: TN0116 | C16: 13 | D16: Rev. R. Stanley Joansraj | E16: Vanthavasi | F16: 241_ 260 | G16: 241_ 260 | H16: 241_ 260 | I16: Not | J16: 3 | L16: 7 | M16: 7
A17: TN0115 | C17: 14 | D17: Rev. Dr. Swamy Adimai Chinnapavu | E17: Tirnelveli | F17: 261 _ 280 | G17: 261 _ 280 | H17: 261 _ 280 | I17: Returned
A18: TN0106 | C18: 15 | D18: Rev. K. Robert Kennady | E18: Bangalore | F18: 281 _300 | G18: 281 _300 | H18: 281 _300 | I18: Not
A19: TN0099 | C19: 16 | D19: Rev. T. Sebastian | E19: Pandicherry | F19: 301_ 320 | G19: 301_ 320 | H19: 301_ 320 | I19: Not
A20: TN0102 | C20: 17 | D20: Rev. M. Yesudas | E20: Munnar | F20: 321_ 340 | G20: 321_ 340 | H20: 321_ 340 | I20: Not
A21: TN0125 | C21: 18 | D21: Rev. G. P. Arockia Swamy | E21: Kanchipuram | F21: 341 _360 | G21: 341 _360 | H21: 341 _360 | I21: Returned
A22: TN0218 | D22: Rev. A. Arul | F22: 341 _360 | G22: 341 _360 | H22: 341 _360 | I22: Not | K22: 2
A23: TN0101 | C23: 19 | D23: Rev.D. Ezekiel | E23: Coimbatore | F23: 361 _380 | G23: 361 _380 | H23: 361 _380 | I23: Returned | L23: 2
A24: TN0241 | C24: 20 | D24: Rev. S. P. Yesupaul | E24: Nellai | F24: 381 _400 | G24: 381 _400 | H24: 381 _400 | I24: Returned | K24: 3
A25: TN0268 | C25: 21 | D25: Rev. S. S. Paul | E25: Mayiladuthurai | F25: 401 _420 | G25: 401 _420 | H25: 401 _420 | I25: Not
A26: TN0187 | C26: 22 | D26: Rev. F. Anthony Raj | E26: Tiruchirapalli | F26: 421 _440 | G26: 421 _440 | H26: 421 _440 | I26: Not | L26: 2
A27: TN0230 | C27: 23 | D27: Rev. S. Lazarus | E27: Cheyyaam | F27: 441 _460 | G27: 441 _460 | H27: 441 _460 | I27: Returned
A28: TN0283 | B28: 12.03.2015 | C28: 24 | D28: Rev. Y. Santha Kumar | E28: Krishnagiri | F28: 461- 480 | G28: 461- 480 | H28: 461- 480 | I28: Returned
A29: TN0373 | B29: 04.08.2015 | C29: 25 | D29: Rev. C. Paul | E29: Chittoor | F29: 481 - 500 | G29: 481 - 500 | H29: 481 - 500 | I29: Not | K29: 1 | N29: 1
A30: TN0166 | B30: 16.10.2016 | C30: 26 | D30: Rev. C. Daniel Kesavan | E30: Vellore | F30: 501 -520 | G30: 501 -520 | H30: 501 -520 | I30: Returned
A31: TN0413 | B31: 09.02.2016 | C31: 27 | D31: Rev. S. Anand | E31: Kanchipuram | F31: 521 - 540 | G31: 521 - 540 | H31: 521 - 540 | I31: Not | K31: 1 | L31: 1
A32: TN0470 | C32: 28 | D32: Rev. J. Solomon | E32: Gantur | F32: 541 - 560 | G32: 541 - 560 | H32: 541 - 560 | I32: Not
A33: TN0048 | B33: 19.04.2016 | C33: 29 | D33: Rev. A. Chinnappadoss | E33: Sivakasi | F33: 561 - 580 | G33: 561 - 580 | H33: 561 - 580 | I33: Not | L33: 1 | M33: 3
A34: TN0404 | C34: 30 | D34: Rev. J. P. Joni Edwin Raj | E34: Kanniyakumari | F34: 581 -600 | G34: 581 -600 | H34: 581 -600 | I34: Not
A35: TN0473 | C35: 31 | D35: Rev. J. Paul Durai | E35: Mumbi | F35: 601 - 620 | G35: 601 - 620 | H35: 601 - 620 | I35: Not
A36: TN0079 | B36: 21.01.2017 | C36: 20 | D36: Rev. D. K. Deva Athisayam | E36: Tirunelveli | F36: 381 - 400 | G36: 381 - 400 | H36: 381 - 400 | I36: Not | N36: 2
A37: TN0249 | B37: 19.04.2017 | C37: 32 | D37: Rev. P. Santhosam | E37: Kanchipuram | F37: 621 -640 | G37: 621 -640 | H37: 621 -640 | I37: Not
A38: TN0536 | B38: 12.04.2018 | C38: 26 A | D38: Rev. D. Bala Justin Raj | E38: Madurai | F38: 26 - 30 | G38: 26 - 30 | H38: 26 - 30 | I38: Not
A39: TN0534 | B39: 26.04.2018 | C39: 26 B | D39: Rev. M. Martin Munisamy | E39: Ramanathapuram | F39: 31 - 35 | G39: 31 - 35 | H39: 31 - 35 | I39: Not | N39: 1
A40: TN0165 | B40: 26.04.2018 | C40: 26 C | D40: Rev. S. Yesumuthu | E40: Coimbatore | F40: 36 - 40 | G40: 36 - 40 | H40: 36 - 40 | I40: Returned | L40: 3 | M40: 1 | N40: 3 | O40: 1
...

Sheet Sheet1
